// pow.cpp: test suite runner for power function
//
// Copyright (C) 2017 Stillwater Supercomputing, Inc.
//
// This file is part of the universal numbers project, which is released under an MIT Open Source license.
#include <universal/utility/directives.hpp>
#include <universal/number/lns/lns.hpp>
#include <universal/verification/lns_test_suite_mathlib.hpp>

// generate specific test case that you can trace with the trace conditions in lns.hpp
// for most bugs they are traceable with _trace_conversion and _trace_add
template<size_t nbits, size_t rbits, typename bt, typename Ty>
void GenerateTestCase(Ty a, Ty b) {
	Ty ref;
	sw::universal::lns<nbits, rbits, bt> pa{}, pb{}, pref{}, ppow{};
	pa = a;
	pb = b;
	ref = std::pow(a,b);
	pref = ref;
	ppow = sw::universal::pow(pa,pb);
	std::cout << std::setprecision(nbits - 2);
	std::cout << std::setw(nbits) << " -> pow(" << a << "," << b << ") = " << std::setw(nbits) << ref << std::endl;
	std::cout << " -> pow( " << pa << "," << pb << ") = " << ppow.get() << " (reference: " << pref.get() << ")   " ;
	std::cout << (pref == ppow ? "PASS" : "FAIL") << std::endl << std::endl;
	std::cout << std::setprecision(5);
}

#define MANUAL_TESTING 0
#define STRESS_TESTING 0

int main()
try {
	using namespace sw::universal;

	std::string test_suite  = "lns<> mathlib power function validation";
	std::string test_tag    = "pow";
	bool reportTestCases    = false;
	int nrOfFailedTestCases = 0;

	ReportTestSuiteHeader(test_suite, reportTestCases);

#if MANUAL_TESTING
	// generate individual testcases to hand trace/debug
	GenerateTestCase<16, 1, std::uint16_t, float>(4.0f, 2.0f);

#if GENERATE_POW_TABLES
	GeneratePowTable<3, 0>();
	GeneratePowTable<4, 0>();
	GeneratePowTable<4, 1>();
	GeneratePowTable<5, 0>();
	GeneratePowTable<5, 1>();
	GeneratePowTable<5, 2>();
	GeneratePowTable<6, 0>();
	GeneratePowTable<6, 1>();
	GeneratePowTable<6, 2>();
	GeneratePowTable<6, 3>();
	GeneratePowTable<7, 0>();
#endif

	nrOfFailedTestCases += ReportTestResult(VerifyPowerFunction<4, 1>("Manual Testing", reportTestCases), "lns<4,1>", test_tag);

	nrOfFailedTestCases += ReportTestResult(VerifyPowerFunction<5, 2>("Manual Testing", reportTestCases), "lns<5,2>", test_tag);

	nrOfFailedTestCases += ReportTestResult(VerifyPowerFunction<8, 4>("Manual Testing", reportTestCases), "lns<8,4>", test_tag);

	//nrOfFailedTestCases += ReportTestResult(VerifyPowerFunction<16, 1>("Manual Testing", reportTestCases), "lns<16,1>", test_tag);

	ReportTestSuiteResults(test_suite, nrOfFailedTestCases);
	return EXIT_SUCCESS;   // ignore errors
#else

	nrOfFailedTestCases += ReportTestResult(VerifyPowerFunction< lns<8, 2> >(reportTestCases), "lns<8,2>", "pow");

	ReportTestSuiteResults(test_suite, nrOfFailedTestCases);
	return (nrOfFailedTestCases > 0 ? EXIT_FAILURE : EXIT_SUCCESS);

#endif  // MANUAL_TESTING
}
catch (char const* msg) {
	std::cerr << "Caught ad-hoc exception: " << msg << std::endl;
	return EXIT_FAILURE;
}
catch (const sw::universal::universal_arithmetic_exception& err) {
	std::cerr << "Caught unexpected universal arithmetic exception : " << err.what() << std::endl;
	return EXIT_FAILURE;
}
catch (const sw::universal::universal_internal_exception& err) {
	std::cerr << "Caught unexpected universal internal exception: " << err.what() << std::endl;
	return EXIT_FAILURE;
}
catch (const std::runtime_error& err) {
	std::cerr << "Caught runtime exception: " << err.what() << std::endl;
	return EXIT_FAILURE;
}
catch (...) {
	std::cerr << "Caught unknown exception" << std::endl;
	return EXIT_FAILURE;
}
